<?xml version="1.0" ?>
<!-- =================================================================================== -->
<!-- |    This document was autogenerated by xacro from jaco_on_table_robot.urdf.xacro | -->
<!-- |    EDITING THIS FILE BY HAND IS NOT RECOMMENDED                                 | -->
<!-- =================================================================================== -->
<robot name="JacoOnTable" xmlns:controller="http://playerstage.sourceforge.net/gazebo/xmlschema/#controller" xmlns:interface="http://playerstage.sourceforge.net/gazebo/xmlschema/#interface" xmlns:sensor="http://playerstage.sourceforge.net/gazebo/xmlschema/#sensor" xmlns:xacro="http://ros.org/wiki/xacro">
  <!--
	<link name="jaco_on_table_root">
		<static>false</static>
	</link>
-->
  <link name="world"/>
  <!-- add transmission tags for position controllers -->
  <!-- add transmission tags for velocity controllers -->
  <!-- IMPORTANT NOTE about arm and finger limits: These values are optimized for mass dividers between 2 (for fingers 1-3)
         for using gazebo_ros_control hardware interface controllers.
         The seemingly most important factor in making robots explode is too much force allowed. Higher PID gains don't have too
         much of an effect. Should maybe start testing with higher PID values to challenge hitting the max force.
         The mass also plays a role. The lighter the robot, the easier it explodes when movements are made.
         When it is heavy, it is harder to lift the arm, and when it moves down, there's a risk of it collapsing down and then exploding after.
         For fingers: with current values, it works only with starting from 1.1 - 1.0 doesn't move. When it's too high, the robot explodes (last tested with finger mass div 1). 
         Velocity was tested between 0.1 and 0.3 but not sure it has an effect.  
         UPDATE 30.1: reducing the damping and friction for some joints has greatly improved the outcome. Damping/Friction probably also has played a roll in the robot collapses. -->
  <!-- Note for reading this in gazebo model (2015): effort and velocity limits are not yet imported properly in gazebo. 
         Update the driver after it does! Now it's hard-coded in C Macros -->
  <!--- remark 2014: damping greater than 0.5 lead to model break downs when testing it bit by bit -->
  <!-- Formula according to https://en.wikipedia.org/wiki/List_of_moment_of_inertia_tensors for cylinder -->
  <!-- fake cylinder which is actually a box -->
  <!--xacro:macro name="cyl_inertia" params="mass r h ">
      <mass value="${mass}"/>
      <inertia
      ixx="${mass / 12.0 * (r*r + h*h)}" ixy="0.0" ixz="0.0"
      iyy="${mass / 12.0 * (h*h + r*r)}" iyz="0.0"
      izz="${mass / 12.0 * (r*r + r*r)}"/>
  </xacro:macro-->
  <!-- ***************** MODEL CORRECTIONS ************************* -->
  <!-- MODEL_FIX corrections for hand limb, which is not modelled correctly. 
  <xacro:property name="wrist_scale_x" value="1.12"/>
  <xacro:property name="wrist_scale_y" value="1.05"/>
  <xacro:property name="wrist_scale_z" value="1.05"/>
  -->
  <!-- MODEL_FIX transform of base to first joint as derived from DH specs is not exact, this is a correction 
  <xacro:property name="base_height_corr" value="-0.005"/>
  <xacro:property name="base_height_corr" value="-0.005"/>
-->
  <!-- MODEL_FIX finger tip visuals are not long enough -->
  <!--
  <xacro:property name="tip_scale_x" value="1.17"/>
  <xacro:property name="tip_scale_y" value="1"/>
  <xacro:property name="tip_scale_z" value="1"/>
  -->
  <!-- *************************************************************** -->
  <!-- MODEL_FIX transforms from wrist to finger joints. Measures from the kinova spec image (Hand.png), pitch angles calculated from measures and experimentally adapted -->
  <!--<xacro:property name="f_thb_xyz" value=" 0.0319  0.003  0.1214" />
  <xacro:property name="f_idx_xyz" value="-0.0276  0.0204 0.1214" />
  <xacro:property name="f_pnk_xyz" value="-0.0276 -0.0204 0.1214" /> -->
  <!-- from measurements, pitch is -0.2658 -->
  <!-- from measurements, pitch is -0.2293 -->
  <!-- from measurements, pitch is -0.2293 -->
  <!-- MODEL_FIX transforms from wrist to finger mounts -->
  <!--<xacro:property name="f_thb_m_xyz" value=" 0.037  0.001  0.106" />
  <xacro:property name="f_idx_m_xyz" value="-0.034  0.022 0.106" />
  <xacro:property name="f_pnk_m_xyz" value="-0.034 -0.022 0.106" />
  <xacro:property name="f_thb_m_rpy" value="0 -0.2658 ${M_PI-0.226892}" /> 
  <xacro:property name="f_idx_m_rpy" value="0 -0.2293 -0.191986" />
  <xacro:property name="f_pnk_m_rpy" value="0 -0.2293 0.191986" />-->
  <!-- MACRO FOR THE ROBOT ARM -->
  <!-- MACRO FOR THE ROBOT ARM ON THE TABLE-->
  <!-- see jaco.urdf.xacro parameters of same name -->
  <joint name="base_to_jaco_on_table" type="fixed">
    <origin rpy="0 0 0" xyz="0 0 0"/>
    <parent link="world"/>
    <child link="robot_base"/>
  </joint>
  <link name="robot_base">
    <static>false</static>
  </link>
  <xacro:property name="t_width" value="1.05"/>
  <xacro:property name="t_height" value="0.8"/>
  <xacro:property name="t_thickness" value="0.03"/>
  <xacro:property name="rim_height" value="0.015"/>
  <xacro:property name="rim_thickness" value="0.005"/>
  <gazebo reference="table_base">
    <material>Gazebo/FlatBlack</material>
  </gazebo>
  <gazebo reference="table_top">
    <material>Gazebo/White</material>
  </gazebo>
  <link name="table_base">
    <inertial>
      <origin rpy="0 0 0" xyz="0.018511509179121 0.23251932391586 1.175991980646075"/>
      <mass value="12.6503207764878"/>
      <inertia ixx="1.69157982834144" ixy="-1.62908934773947E-14" ixz="-9.74479440236252E-15" iyy="3.23322704330012" iyz="-1.84123364573924E-14" izz="2.59218197995528"/>
    </inertial>
    <visual>
      <origin rpy="0 0 0" xyz="0 0 0"/>
      <geometry>
        <mesh filename="package://jaco_on_table/meshes/objects/table_base.STL"/>
      </geometry>
      <material name="">
        <color rgba="0.192156862745098 0.203921568627451 0.203921568627451 1"/>
      </material>
    </visual>
    <collision>
      <origin rpy="0 0 0" xyz="0 0 0"/>
      <geometry>
        <mesh filename="package://jaco_on_table/meshes/objects/table_base.STL"/>
      </geometry>
    </collision>
  </link>
  <link name="table_top">
    <inertial>
      <origin rpy="0 0 0" xyz="2.18575157973078E-16 0.0165 -1.11022302462516E-16"/>
      <mass value="27.72"/>
      <inertia ixx="1.48091559" ixy="-4.70197740328915E-35" ixz="1.33744867033177E-16" iyy="4.025175" iyz="0" izz="2.54929059"/>
    </inertial>
    <visual>
      <origin rpy="0 0 0" xyz="0 0 0"/>
      <geometry>
        <mesh filename="package://jaco_on_table/meshes/objects/table_top.STL"/>
      </geometry>
      <material name="">
        <color rgba="1 1 1 1"/>
      </material>
    </visual>
    <visual>
      <origin rpy="0 0 0" xyz="0 0.0375 -0.3975"/>
      <geometry>
        <box size="1.05 0.015 0.005"/>
      </geometry>
      <material name="">
        <color rgba="0.8 0.8 1 1"/>
      </material>
    </visual>
    <visual>
      <origin rpy="0 0 0" xyz="0.5225 0.0375 0"/>
      <geometry>
        <box size="0.005 0.015 0.8"/>
      </geometry>
      <material name="">
        <color rgba="0.8 0.8 1 1"/>
      </material>
    </visual>
    <collision>
      <origin rpy="0 0 0" xyz="0 0.0375 -0.3975"/>
      <geometry>
        <box size="1.05 0.015 0.005"/>
      </geometry>
    </collision>
    <collision>
      <origin rpy="0 0 0" xyz="0.5225 0.0375 0"/>
      <geometry>
        <box size="0.005 0.015 0.8"/>
      </geometry>
    </collision>
    <collision>
      <origin rpy="0 0 0" xyz="0 0 0"/>
      <geometry>
        <mesh filename="package://jaco_on_table/meshes/objects/table_top.STL"/>
      </geometry>
    </collision>
  </link>
  <joint name="j1" type="fixed">
    <origin rpy="1.5707963267949 0 0" xyz="0.0185115091791201 -0.175991980646074 0.397575968372377"/>
    <parent link="table_base"/>
    <child link="table_top"/>
    <axis xyz="0 0 0"/>
  </joint>
  <!-- Add some handy co-ordinate frames -->
  <link name="tabletop_ontop"/>
  <joint name="table_tabletop_totop" type="fixed">
    <origin rpy="-1.57079632679 0 0" xyz="0.0 0.033 0"/>
    <parent link="table_top"/>
    <child link="tabletop_ontop"/>
    <axis xyz="0 0 0"/>
  </joint>
  <link name="tabletop_corner"/>
  <joint name="set_tabletop_relto_corner" type="fixed">
    <origin rpy="0 0 -0.76" xyz="0.42 0.3 0"/>
    <!-- exact 45 degrees of -0.785398163397458 does not match the real table -->
    <parent link="tabletop_ontop"/>
    <child link="tabletop_corner"/>
  </joint>
  <joint name="table_to_arm" type="fixed">
    <origin rpy="0 0 -0.785398163397458" xyz="0.40488474042 0.27988474042 0.3"/>
    <parent link="robot_base"/>
    <child link="table_base"/>
  </joint>
  <gazebo reference="arm_stand">
    <material>Gazebo/FlatBlack</material>
  </gazebo>
  <link name="arm_stand">
    <inertial>
      <origin rpy="0 0 0" xyz="2.55087129061304E-06 0.0160653225793 0.0184477855302965"/>
      <mass value="0.355288327861601"/>
      <inertia ixx="0.000857343821996639" ixy="6.2983660131078E-08" ixz="-3.19177822902163E-08" iyy="0.0019174970781523" iyz="-8.19713905978223E-05" izz="0.00176131215859239"/>
    </inertial>
    <visual>
      <origin rpy="0 0 0" xyz="0 0 0"/>
      <geometry>
        <mesh filename="package://jaco_on_table/meshes/objects/arm_stand.STL"/>
      </geometry>
      <material name="">
        <color rgba="0.192156862745098 0.203921568627451 0.203921568627451 1"/>
      </material>
    </visual>
    <collision>
      <origin rpy="0 0 0" xyz="0 0 0"/>
      <geometry>
        <mesh filename="package://jaco_on_table/meshes/objects/arm_stand.STL"/>
      </geometry>
    </collision>
  </link>
  <joint name="j2b" type="fixed">
    <origin rpy="-1.57079632679 -3.14159265358979 0" xyz="0 -0.035 0"/>
    <!-- set the arm "inside" the table for now because of the rim along the real table. creating a bit of a buffer zone so moveit trajectories are within safe distance of the table edges. -->
    <parent link="tabletop_corner"/>
    <child link="arm_stand"/>
    <axis xyz="0 0 0"/>
  </joint>
  <!-- Add the JACO arm to the given parent link with the given transforms -->
  <joint name="jaco_arm_joint" type="fixed">
    <origin rpy="1.57079632679 0 3.14159265359" xyz="-0.000482247085224208 0.08 -0.000503436190578577"/>
    <parent link="arm_stand"/>
    <child link="jaco_0_baseA"/>
  </joint>
  <!-- for some reason, material only applies if full name specified...
       these only seem to work in older gazebo versions -->
  <gazebo reference="jaco_ring_">
    <material>Gazebo/Grey</material>
    <implicitSpringDamper>1</implicitSpringDamper>
    <mu1>100000</mu1>
    <mu2>100000</mu2>
    <kp>100000000.0</kp>
    <kd>1.0</kd>
  </gazebo>
  <gazebo reference="_limb">
    <material>Gazebo/FlatBlack</material>
    <implicitSpringDamper>1</implicitSpringDamper>
    <mu1>100000</mu1>
    <mu2>100000</mu2>
    <kp>100000000.0</kp>
    <kd>1.0</kd>
  </gazebo>
  <gazebo reference="_finger">
    <material>Gazebo/Grey</material>
    <implicitSpringDamper>1</implicitSpringDamper>
    <mu1>100000</mu1>
    <mu2>100000</mu2>
    <kp>100000000.0</kp>
    <kd>1.0</kd>
  </gazebo>
  <!-- for some reason, material only applies if full name specified -->
  <gazebo reference="jaco_0_baseA">
    <material>Gazebo/White</material>
    <mu1>100000</mu1>
    <mu2>100000</mu2>
    <kp>100000000.0</kp>
    <kd>1.0</kd>
  </gazebo>
  <gazebo reference="jaco_0_baseB_limb">
    <material>Gazebo/FlatBlack</material>
    <mu1>100000</mu1>
    <mu2>100000</mu2>
    <kp>100000000.0</kp>
    <kd>1.0</kd>
  </gazebo>
  <gazebo reference="jaco_ring_1">
    <material>Gazebo/Grey</material>
    <mu1>100000</mu1>
    <mu2>100000</mu2>
    <kp>100000000.0</kp>
    <kd>1.0</kd>
  </gazebo>
  <gazebo reference="jaco_ring_2">
    <material>Gazebo/Grey</material>
    <mu1>100000</mu1>
    <mu2>100000</mu2>
    <kp>100000000.0</kp>
    <kd>1.0</kd>
  </gazebo>
  <gazebo reference="jaco_ring_3">
    <material>Gazebo/Grey</material>
    <mu1>100000</mu1>
    <mu2>100000</mu2>
    <kp>100000000.0</kp>
    <kd>1.0</kd>
  </gazebo>
  <gazebo reference="jaco_ring_4">
    <material>Gazebo/Grey</material>
    <mu1>100000</mu1>
    <mu2>100000</mu2>
    <kp>100000000.0</kp>
    <kd>1.0</kd>
  </gazebo>
  <gazebo reference="jaco_ring_5">
    <material>Gazebo/Grey</material>
    <mu1>100000</mu1>
    <mu2>100000</mu2>
    <kp>100000000.0</kp>
    <kd>1.0</kd>
  </gazebo>
  <gazebo reference="jaco_ring_6">
    <material>Gazebo/Grey</material>
    <mu1>100000</mu1>
    <mu2>100000</mu2>
    <kp>100000000.0</kp>
    <kd>1.0</kd>
  </gazebo>
  <gazebo reference="jaco_1_shoulder_limb">
    <material>Gazebo/FlatBlack</material>
    <mu1>100000</mu1>
    <mu2>100000</mu2>
    <kp>100000000.0</kp>
    <kd>1.0</kd>
  </gazebo>
  <gazebo reference="jaco_2_upperarm_limb">
    <material>Gazebo/FlatBlack</material>
    <mu1>100000</mu1>
    <mu2>100000</mu2>
    <kp>100000000.0</kp>
    <kd>1.0</kd>
  </gazebo>
  <gazebo reference="jaco_3_forearm_limb">
    <material>Gazebo/FlatBlack</material>
    <mu1>100000</mu1>
    <mu2>100000</mu2>
    <kp>100000000.0</kp>
    <kd>1.0</kd>
  </gazebo>
  <gazebo reference="jaco_4_upperwrist_limb">
    <material>Gazebo/FlatBlack</material>
    <mu1>100000</mu1>
    <mu2>100000</mu2>
    <kp>100000000.0</kp>
    <kd>1.0</kd>
  </gazebo>
  <gazebo reference="jaco_5_lowerwrist_limb">
    <material>Gazebo/FlatBlack</material>
    <mu1>100000</mu1>
    <mu2>100000</mu2>
    <kp>100000000.0</kp>
    <kd>1.0</kd>
  </gazebo>
  <gazebo reference="jaco_6_hand_limb">
    <material>Gazebo/FlatBlack</material>
    <mu1>100000</mu1>
    <mu2>100000</mu2>
    <kp>100000000.0</kp>
    <kd>1.0</kd>
  </gazebo>
  <gazebo reference="jaco_fingers_base_link">
    <material>Gazebo/FlatBlack</material>
    <mu1>100000</mu1>
    <mu2>100000</mu2>
    <kp>100000000.0</kp>
    <kd>1.0</kd>
  </gazebo>
  <gazebo reference="jaco_7_finger_mount_index">
    <material>Gazebo/FlatBlack</material>
    <mu1>100000</mu1>
    <mu2>100000</mu2>
    <kp>100000000.0</kp>
    <kd>1.0</kd>
  </gazebo>
  <gazebo reference="jaco_7_finger_mount_thumb">
    <material>Gazebo/FlatBlack</material>
    <mu1>100000</mu1>
    <mu2>100000</mu2>
    <kp>100000000.0</kp>
    <kd>1.0</kd>
  </gazebo>
  <gazebo reference="jaco_7_finger_mount_pinkie">
    <material>Gazebo/FlatBlack</material>
    <mu1>100000</mu1>
    <mu2>100000</mu2>
    <kp>100000000.0</kp>
    <kd>1.0</kd>
  </gazebo>
  <gazebo reference="jaco_8_finger_thumb">
    <material>Gazebo/Grey</material>
    <mu1>100000</mu1>
    <mu2>100000</mu2>
    <kp>100000000.0</kp>
    <kd>1.0</kd>
  </gazebo>
  <gazebo reference="jaco_8_finger_index">
    <material>Gazebo/Grey</material>
    <mu1>100000</mu1>
    <mu2>100000</mu2>
    <kp>100000000.0</kp>
    <kd>1.0</kd>
  </gazebo>
  <gazebo reference="jaco_8_finger_pinkie">
    <material>Gazebo/Grey</material>
    <mu1>100000</mu1>
    <mu2>100000</mu2>
    <kp>100000000.0</kp>
    <kd>1.0</kd>
  </gazebo>
  <gazebo reference="jaco_9_finger_thumb_tip">
    <material>Gazebo/Grey</material>
    <mu1>100000</mu1>
    <mu2>100000</mu2>
    <kp>100000000.0</kp>
    <kd>1.0</kd>
  </gazebo>
  <gazebo reference="jaco_9_finger_index_tip">
    <material>Gazebo/Grey</material>
    <mu1>100000</mu1>
    <mu2>100000</mu2>
    <kp>100000000.0</kp>
    <kd>1.0</kd>
  </gazebo>
  <gazebo reference="jaco_9_finger_pinkie_tip">
    <material>Gazebo/Grey</material>
    <mu1>100000</mu1>
    <mu2>100000</mu2>
    <kp>100000000.0</kp>
    <kd>1.0</kd>
  </gazebo>
  <gazebo reference="jaco_finger_joint_0">
    <provideFeedback value="true"/>
  </gazebo>
  <gazebo reference="jaco_finger_joint_2">
    <provideFeedback value="true"/>
  </gazebo>
  <gazebo reference="jaco_finger_joint_4">
    <provideFeedback value="true"/>
  </gazebo>
  <link name="jaco_0_baseA">
    <inertial>
      <origin rpy="0 0 0" xyz="0 0 0.03"/>
      <mass value="0.2844"/>
      <inertia ixx="0.000174644601419" ixy="0" ixz="0" iyy="0.000174644601419" iyz="0" izz="0.0001842912"/>
    </inertial>
    <visual>
      <origin rpy="0 0 0" xyz="0 0 0"/>
      <geometry>
        <mesh filename="package://jaco_description/meshes/jaco2/0_baseA.STL" scale="0.98 0.98 0.98"/>
      </geometry>
      <material name="">
        <color rgba="0.65 0.65 0.66 1"/>
      </material>
    </visual>
    <collision>
      <origin rpy="0 0 0" xyz="0 0 0"/>
      <geometry>
        <mesh filename="package://jaco_description/meshes/jaco2/0_baseA.STL"/>
      </geometry>
    </collision>
  </link>
  <!-- ...........................        -->
  <link name="jaco_0_baseB_limb">
    <inertial>
      <origin rpy="0 0 0" xyz="0 0.04725 0"/>
      <mass value="0.2576"/>
      <inertia ixx="0.000294741521029" ixy="0" ixz="0" iyy="0.000294741521029" iyz="0" izz="0.00020608"/>
    </inertial>
    <visual>
      <origin rpy="0 0 0" xyz="0 0 0"/>
      <geometry>
        <mesh filename="package://jaco_description/meshes/jaco2/0_baseB_limb.STL"/>
      </geometry>
      <material name="">
        <color rgba="0.10 0.10 0.10 1"/>
      </material>
    </visual>
    <collision>
      <origin rpy="0 0 0" xyz="0 0 0"/>
      <geometry>
        <mesh filename="package://jaco_description/meshes/jaco2/0_baseB_limb.STL"/>
      </geometry>
    </collision>
  </link>
  <joint name="jaco_base_internal" type="fixed">
    <origin rpy="1.57079632679 0 0" xyz="0 0 0.049"/>
    <parent link="jaco_0_baseA"/>
    <child link="jaco_0_baseB_limb"/>
    <axis xyz="0 0 0"/>
  </joint>
  <link name="jaco_ring_1">
    <inertial>
      <origin rpy="0 0 0" xyz="-3.57503886452221E-16 -1.58125151997128E-15 -5.55111512312578E-17"/>
      <mass value="0.00436"/>
      <inertia ixx="1.889325776e-06" ixy="0" ixz="0" iyy="1.889325776e-06" iyz="0" izz="3.488e-06"/>
    </inertial>
    <visual>
      <origin rpy="0 0 0" xyz="0 0 0"/>
      <geometry>
        <mesh filename="package://jaco_description/meshes/jaco2/ring_1.STL"/>
      </geometry>
      <material name="">
        <color rgba="0.50 0.50 0.50 1"/>
      </material>
    </visual>
    <collision>
      <origin rpy="0 0 0" xyz="0 0 0"/>
      <geometry>
        <mesh filename="package://jaco_description/meshes/jaco2/ring_1.STL"/>
      </geometry>
    </collision>
  </link>
  <joint name="jaco_ring_1_joint" type="fixed">
    <origin rpy="-1.57079632679 0.211499083190217 -3.14159265359" xyz="0 0.104 0"/>
    <parent link="jaco_0_baseB_limb"/>
    <child link="jaco_ring_1"/>
    <axis xyz="0 0 0"/>
  </joint>
  <!-- ...........................        -->
  <link name="jaco_1_shoulder_limb">
    <inertial>
      <origin rpy="0 0 0" xyz="0.0120470281905243 0.0657132437750733 0"/>
      <mass value="0.2391"/>
      <inertia ixx="0.000599361527544" ixy="0" ixz="0" iyy="0.000599361527544" iyz="0" izz="0.00019128"/>
    </inertial>
    <visual>
      <origin rpy="0 0 0" xyz="0 0 0"/>
      <geometry>
        <mesh filename="package://jaco_description/meshes/jaco2/1_shoulder_limb.STL"/>
      </geometry>
      <material name="">
        <color rgba="0.10 0.10 0.10 1"/>
      </material>
    </visual>
    <!--     <visual>
      <origin xyz="0 0 0" rpy="0 0 0" />
      <geometry>
        <sphere radius="0.005"/>
      </geometry>
      <material name="">
        <color rgba="0.10 0.10 0.10 1" />
      </material>
    </visual>
-->
    <collision>
      <origin rpy="0 0 0" xyz="0 0 0"/>
      <geometry>
        <mesh filename="package://jaco_description/meshes/jaco2/1_shoulder_limb.STL"/>
      </geometry>
    </collision>
  </link>
  <joint name="jaco_arm_0_joint" type="continuous">
    <limit effort="8" velocity="1.0"/>
    <dynamics damping="0.5" friction="0.5"/>
    <origin rpy="0 1.57079632679 0" xyz="0 0.104 0"/>
    <parent link="jaco_0_baseB_limb"/>
    <child link="jaco_1_shoulder_limb"/>
    <axis xyz="0 1 0"/>
  </joint>
  <!-- ...........................        -->
  <link name="jaco_ring_2">
    <inertial>
      <origin rpy="0 0 0" xyz="0 0 0"/>
      <mass value="0.00436"/>
      <inertia ixx="1.889325776e-06" ixy="0" ixz="0" iyy="1.889325776e-06" iyz="0" izz="3.488e-06"/>
    </inertial>
    <visual>
      <origin rpy="0 0 0" xyz="-0.0005 -0.003 -0.001"/>
      <geometry>
        <mesh filename="package://jaco_description/meshes/jaco2/ring_2.STL"/>
      </geometry>
      <material name="">
        <color rgba="0.50 0.50 0.50 1"/>
      </material>
    </visual>
    <collision>
      <origin rpy="0 0 0" xyz="-0.0005 -0.003 -0.001"/>
      <geometry>
        <mesh filename="package://jaco_description/meshes/jaco2/ring_2.STL"/>
      </geometry>
    </collision>
  </link>
  <joint name="jaco_ring_2_joint" type="fixed">
    <origin rpy="-1.57079632679488 -1.49007956532211 1.57079632679488" xyz="0 0.1225 0"/>
    <parent link="jaco_1_shoulder_limb"/>
    <child link="jaco_ring_2"/>
    <axis xyz="0 0 0"/>
  </joint>
  <!-- ...........................        -->
  <link name="jaco_2_upperarm_limb">
    <inertial>
      <origin rpy="0 0 0" xyz="0.206003857152394 0 -0.0343672381612413"/>
      <mass value="0.685815"/>
      <inertia ixx="0.014133619044" ixy="0" ixz="0" iyy="0.014133619044" iyz="0" izz="0.0008233209075"/>
    </inertial>
    <visual>
      <origin rpy="0 0 0" xyz="-0.003 -0.001 -0.001"/>
      <geometry>
        <mesh filename="package://jaco_description/meshes/jaco2/2_upperarm_limb.STL"/>
      </geometry>
      <material name="">
        <color rgba="0.10 0.10 0.10 1"/>
      </material>
    </visual>
    <!--     <visual>
      <origin xyz="0 0 0" rpy="0 0 0" />
      <geometry>
        <sphere radius="0.005"/>
      </geometry>
      <material name="">
        <color rgba="0.10 0.10 0.10 1" />
      </material>
    </visual>
-->
    <collision>
      <origin rpy="0 0 0" xyz="-0.003 -0.001 -0.001"/>
      <geometry>
        <mesh filename="package://jaco_description/meshes/jaco2/2_upperarm_limb.STL"/>
      </geometry>
    </collision>
  </link>
  <joint name="jaco_arm_1_joint" type="revolute">
    <!-- gazebo has a problem with joint limits where lower limit > higher limit (it internally swaps them around). That's why it's limits under -PI. If I chose 2.5..0.73 as limit, gazebo would only let me move the joints within 0.73..2.5. For now, keep it at -3.943..0.81 and publish joint angles NOT between -PI and PI for this joint (otherwise moveit! would recognise e.g. 3. as illegal, although it's legal).-->
    <dynamics damping="0.5" friction="0.5"/>
    <limit effort="8" lower="-3.943" upper="0.81" velocity="1.0"/>
    <origin rpy="3.14159265359 -1.57079632679 0" xyz="0 0.1225 0"/>
    <parent link="jaco_1_shoulder_limb"/>
    <child link="jaco_2_upperarm_limb"/>
    <axis xyz="0 0 1"/>
  </joint>
  <!-- ...........................        -->
  <link name="jaco_ring_3">
    <inertial>
      <origin rpy="0 0 0" xyz="0 0 0"/>
      <mass value="0.00436"/>
      <inertia ixx="1.889325776e-06" ixy="0" ixz="0" iyy="1.889325776e-06" iyz="0" izz="3.488e-06"/>
    </inertial>
    <visual>
      <origin rpy="0 0 0" xyz="0.001 0 0"/>
      <geometry>
        <mesh filename="package://jaco_description/meshes/jaco2/ring_3.STL"/>
      </geometry>
      <material name="">
        <color rgba="0.5 0.5 0.5 1"/>
      </material>
    </visual>
    <collision>
      <origin rpy="0 0 0" xyz="0.001 0 0"/>
      <geometry>
        <mesh filename="package://jaco_description/meshes/jaco2/ring_3.STL"/>
      </geometry>
    </collision>
  </link>
  <joint name="jaco_ring_3_joint" type="fixed">
    <origin rpy="3.14159265359 0 -3.14159265359" xyz="0.41 0 0"/>
    <parent link="jaco_2_upperarm_limb"/>
    <child link="jaco_ring_3"/>
    <axis xyz="0 0 0"/>
  </joint>
  <!-- ........................... -->
  <link name="jaco_3_forearm_limb">
    <inertial>
      <origin rpy="0 0 0" xyz="0.0857562490792731 1.94295959371482E-06 0.0203407295609686"/>
      <mass value="0.337964595"/>
      <inertia ixx="0.00170341923624" ixy="0" ixz="0" iyy="0.00170341923624" iyz="0" izz="0.000162391987898"/>
    </inertial>
    <visual>
      <origin rpy="0 0 0" xyz="0 0 0"/>
      <geometry>
        <mesh filename="package://jaco_description/meshes/jaco2/3_forearm_limb.STL"/>
      </geometry>
      <material name="">
        <color rgba="0.1 0.1 0.1 1"/>
      </material>
    </visual>
    <!--     <visual>
      <origin xyz="0 0 0" rpy="0 0 0" />
      <geometry>
        <sphere radius="0.005"/>
      </geometry>
      <material name="">
        <color rgba="0.10 0.10 0.10 1" />
      </material>
    </visual>
-->
    <collision>
      <origin rpy="0 0 0" xyz="0 0 0"/>
      <geometry>
        <mesh filename="package://jaco_description/meshes/jaco2/3_forearm_limb.STL"/>
      </geometry>
    </collision>
  </link>
  <joint name="jaco_arm_2_joint" type="revolute">
    <!-- see arm_1_joint for commmetns about limits -->
    <limit effort="4" lower="-4.395" upper="1.252" velocity="1.0"/>
    <dynamics damping="0.5" friction="0.5"/>
    <origin rpy="0 0 1.57079632679489" xyz="0.41 0 0"/>
    <parent link="jaco_2_upperarm_limb"/>
    <child link="jaco_3_forearm_limb"/>
    <axis xyz="0 0 1"/>
  </joint>
  <!-- ...........................        -->
  <link name="jaco_ring_4">
    <inertial>
      <origin rpy="0 0 0" xyz="0 0 0"/>
      <mass value="0.00338267061984"/>
      <inertia ixx="1.05736222845e-06" ixy="0" ixz="0" iyy="1.05736222845e-06" iyz="0" izz="1.8418641525e-06"/>
    </inertial>
    <visual>
      <origin rpy="0 0 0" xyz="0 0 0"/>
      <geometry>
        <mesh filename="package://jaco_description/meshes/jaco2/ring_4.STL"/>
      </geometry>
      <material name="">
        <color rgba="0.5 0.5 0.5 1"/>
      </material>
    </visual>
    <collision>
      <origin rpy="0 0 0" xyz="0 0 0"/>
      <geometry>
        <mesh filename="package://jaco_description/meshes/jaco2/ring_4.STL"/>
      </geometry>
    </collision>
  </link>
  <joint name="jaco_ring_4_joint" type="fixed">
    <origin rpy="3.14159265359 -1.57079632679 0" xyz="0.2073 0 0.0098"/>
    <parent link="jaco_3_forearm_limb"/>
    <child link="jaco_ring_4"/>
    <axis xyz="-1 0 0"/>
  </joint>
  <!-- ...........................        -->
  <link name="jaco_4_upperwrist_limb">
    <inertial>
      <origin rpy="0 0 0" xyz="-0.0371070560898082 -0.00912675248782567 -2.44092722145872E-08"/>
      <mass value="0.12275168143"/>
      <inertia ixx="0.000136117976719" ixy="0" ixz="0" iyy="0.000136117976719" iyz="0" izz="6.76509066697e-05"/>
    </inertial>
    <visual>
      <origin rpy="0 0 0" xyz="0 0 0"/>
      <geometry>
        <mesh filename="package://jaco_description/meshes/jaco2/4_upperwrist_limb.STL"/>
      </geometry>
      <material name="">
        <color rgba="0.1 0.1 0.1 1"/>
      </material>
    </visual>
    <!--     <visual>
      <origin xyz="0 0 0" rpy="0 0 0" />
      <geometry>
        <sphere radius="0.005"/>
      </geometry>
      <material name="">
        <color rgba="0.10 0.10 0.10 1" />
      </material>
    </visual>
-->
    <collision>
      <origin rpy="0 0 0" xyz="0 0 0"/>
      <geometry>
        <mesh filename="package://jaco_description/meshes/jaco2/4_upperwrist_limb.STL"/>
      </geometry>
    </collision>
  </link>
  <joint name="jaco_arm_3_joint" type="continuous">
    <limit effort="1.5" velocity="1.0"/>
    <dynamics damping="0.05" friction="0.05"/>
    <origin rpy="-1.57079632679484 0 -3.14159265358951" xyz="0.2073 0 0.0098"/>
    <parent link="jaco_3_forearm_limb"/>
    <child link="jaco_4_upperwrist_limb"/>
    <axis xyz="-1 0 0"/>
  </joint>
  <!-- ...........................        -->
  <link name="jaco_ring_5">
    <inertial>
      <origin rpy="0 0 0" xyz="-1.54831009124834E-13 4.27435864480685E-15 -2.58654209162046E-13"/>
      <mass value="0.00338267061984"/>
      <inertia ixx="1.05736222845e-06" ixy="0" ixz="0" iyy="1.05736222845e-06" iyz="0" izz="1.8418641525e-06"/>
    </inertial>
    <visual>
      <origin rpy="0 0 0" xyz="0 0 0"/>
      <geometry>
        <mesh filename="package://jaco_description/meshes/jaco2/ring_5.STL"/>
      </geometry>
      <material name="">
        <color rgba="0.5 0.5 0.5 1"/>
      </material>
    </visual>
    <collision>
      <origin rpy="0 0 0" xyz="0 0 0"/>
      <geometry>
        <mesh filename="package://jaco_description/meshes/jaco2/ring_5.STL"/>
      </geometry>
    </collision>
  </link>
  <joint name="jaco_ring_5_joint" type="fixed">
    <origin rpy="-1.57079632679506 0 -0.610865238196312" xyz="-0.06590490 -0.034307921 0"/>
    <parent link="jaco_4_upperwrist_limb"/>
    <child link="jaco_ring_5"/>
    <axis xyz="-1 0 0"/>
  </joint>
  <!-- ...........................        -->
  <link name="jaco_5_lowerwrist_limb">
    <inertial>
      <origin rpy="0 0 0" xyz="-0.0176083455436658 -0.00912672231835664 -5.99117305766228E-09"/>
      <mass value="0.12275"/>
      <inertia ixx="0.0001361161122" ixy="0" ixz="0" iyy="0.0001361161122" iyz="0" izz="6.764998e-05"/>
    </inertial>
    <visual>
      <origin rpy="0 0 0" xyz="-0.01715 0 0"/>
      <geometry>
        <mesh filename="package://jaco_description/meshes/jaco2/5_lowerwrist_limb.STL"/>
      </geometry>
      <material name="">
        <color rgba="0.1 0.1 0.1 1"/>
      </material>
    </visual>
    <!--     <visual>
      <origin xyz="0 0 0" rpy="0 0 0" />
      <geometry>
        <sphere radius="0.005"/>
      </geometry>
      <material name="">
        <color rgba="0.10 0.10 0.10 1" />
      </material>
    </visual>
-->
    <collision>
      <origin rpy="0 0 0" xyz="-0.01715 0 0"/>
      <geometry>
        <mesh filename="package://jaco_description/meshes/jaco2/5_lowerwrist_limb.STL"/>
      </geometry>
    </collision>
  </link>
  <joint name="jaco_arm_4_joint" type="continuous">
    <limit effort="1.0" velocity="1.0"/>
    <dynamics damping="0.05" friction="0.05"/>
    <!-- caluclated form DH-Parameter documentation. An iscoceles triangle with tip angle 55 degrees has base angles (gamma) 62.5.
       Base has length 74.3. Then sin(gamma)=y/74.3 and cos(gamma)=x/74.3, hence y=65.90590 and x=34.307921963  -->
    <origin rpy="0 0 0.959931089" xyz="-0.06590490 -0.034307921 0"/>
    <parent link="jaco_4_upperwrist_limb"/>
    <child link="jaco_5_lowerwrist_limb"/>
    <axis xyz="-1 0 0"/>
  </joint>
  <!-- ...........................        -->
  <link name="jaco_ring_6">
    <inertial>
      <origin rpy="0 0 0" xyz="2.12629684692711E-10 7.53045514834128E-10 3.03666577994299E-10"/>
      <mass value="0.00338"/>
      <inertia ixx="1.05652744054e-06" ixy="0" ixz="0" iyy="1.05652744054e-06" iyz="0" izz="1.84041e-06"/>
    </inertial>
    <visual>
      <origin rpy="0 0 0" xyz="-0.001 0 0"/>
      <geometry>
        <mesh filename="package://jaco_description/meshes/jaco2/ring_6.STL"/>
      </geometry>
      <material name="">
        <color rgba="0.5 0.5 0.5 1"/>
      </material>
    </visual>
    <collision>
      <origin rpy="0 0 0" xyz="-0.001 0 0"/>
      <geometry>
        <mesh filename="package://jaco_description/meshes/jaco2/ring_6.STL"/>
      </geometry>
    </collision>
  </link>
  <joint name="jaco_ring_6_joint" type="fixed">
    <origin rpy="1.57079632679 0 2.53072741539211 " xyz="-0.06590490 -0.034307921 0"/>
    <parent link="jaco_5_lowerwrist_limb"/>
    <child link="jaco_ring_6"/>
    <axis xyz="0 0 0"/>
  </joint>
  <!-- ...........................        -->
  <link name="jaco_6_hand_limb">
    <inertial>
      <origin rpy="0 0 0" xyz="-0.0555917045329114 -7.25586546752172E-05 -0.00317411883668722"/>
      <!-- ORIGINAL: xacro:cyl_inertia mass="${0.58366/mass_divider}" h="0.104" r="0.11"/-->
      <mass value="0.1"/>
      <inertia ixx="0.0003926317628" ixy="0" ixz="0" iyy="0.0003926317628" iyz="0" izz="0.000605"/>
    </inertial>
    <visual>
      <origin rpy="0 0 0" xyz="0 0 0"/>
      <geometry>
        <mesh filename="package://jaco_description/meshes/jaco2/6_hand_limb.STL" scale="1.0 1.0 1.0"/>
      </geometry>
      <material name="">
        <color rgba="0.1 0.1 0.1 1"/>
      </material>
    </visual>
    <!--     <visual>
      <origin xyz="0 0 0" rpy="0 0 0" />
      <geometry>
        <sphere radius="0.005"/>
      </geometry>
      <material name="">
        <color rgba="0.10 0.10 0.10 1" />
      </material>
    </visual>
-->
    <collision>
      <origin rpy="0 0 0" xyz="0 0 0"/>
      <geometry>
        <mesh filename="package://jaco_description/meshes/jaco2/6_hand_limb.STL" scale="1.0 1.0 1.0"/>
      </geometry>
    </collision>
  </link>
  <joint name="jaco_arm_5_joint" type="continuous">
    <limit effort="1.0" velocity="1.0"/>
    <dynamics damping="0.05" friction="0.05"/>
    <!-- added some experimental angle changes to the arm wrist, as this was not accurate .. tried to touch the base with the hand, and it didn't look the same
    in rviz. I tuned the values so rviz would show same position. However, it's likely this can be better fine tuned -->
    <origin rpy="-1.57079632679 0 0.959931089" xyz="-0.06590490 -0.034307921 0"/>
    <parent link="jaco_5_lowerwrist_limb"/>
    <child link="jaco_6_hand_limb"/>
    <axis xyz="-1 0 0"/>
  </joint>
  <link name="jaco_fingers_base_link">
    <inertial>
      <origin rpy="0 0 0" xyz="0 0 0"/>
      <mass value="0.0005"/>
      <inertia ixx="1.66666e-08" ixy="0" ixz="0" iyy="1.66666e-08" iyz="0" izz="2.5e-08"/>
    </inertial>
  </link>
  <!-- this joint is only to align the coordinate system with the kinova specification frame -->
  <joint name="jaco_fingers_base_joint" type="fixed">
    <origin rpy="-1.57079632679 3.14159265359 1.57079632679" xyz="0 0 0"/>
    <parent link="jaco_6_hand_limb"/>
    <child link="jaco_fingers_base_link"/>
  </joint>
  <!-- ...........................  -->
  <!--      FINGERS          -->
  <!-- ...........................  -->
  <link name="jaco_7_finger_mount_index">
    <inertial>
      <origin rpy="0 0 0" xyz="0 0.00706399246397285 -0.00176078508424846"/>
      <mass value="0.006465"/>
      <inertia ixx="7.8441686232e-07" ixy="0" ixz="0" iyy="7.8441686232e-07" iyz="0" izz="1.04733e-06"/>
    </inertial>
    <visual>
      <origin rpy="1.57079632679 0 1.57079632679" xyz="0 0 0"/>
      <geometry>
        <mesh filename="package://jaco_description/meshes/jaco2/7_finger_mount_index.STL"/>
      </geometry>
      <material name="">
        <color rgba="0.5 0.5 0.5 1"/>
      </material>
    </visual>
    <collision>
      <origin rpy="1.57079632679 0 1.57079632679" xyz="0 0 0"/>
      <geometry>
        <mesh filename="package://jaco_description/meshes/jaco2/7_finger_mount_index.STL"/>
      </geometry>
    </collision>
  </link>
  <joint name="jaco_finger_mount_index_fixed" type="fixed">
    <!--- remark 2014: damping greater than 0.1 (0.2) lead to model break downs when testing it bit by bit -->
    <!--- remark jan 2016: damping and friction higher than 0.005 required very high forces in order for the fingers
              to move at all, and then they mooved only slowly. -->
    <!--dynamics damping="0.1" friction="1.0"/-->
    <dynamics damping="0.005" friction="0.005"/>
    <origin rpy="0 -0.2293 -0.191986" xyz="-0.034  0.022 0.095"/>
    <parent link="jaco_fingers_base_link"/>
    <child link="jaco_7_finger_mount_index"/>
    <axis xyz="0 0 0"/>
  </joint>
  <!-- ...........................        -->
  <link name="jaco_8_finger_index">
    <inertial>
      <origin rpy="0 0 0" xyz="-0.0181403689626489 0 0.00272470933850985"/>
      <mass value="0.01845"/>
      <inertia ixx="6.37560262249e-06" ixy="0" ixz="0" iyy="6.37560262249e-06" iyz="0" izz="1.68125625e-06"/>
    </inertial>
    <!--     <visual>
      <origin xyz="0 0 0" rpy="0 0 0" />
      <geometry>
        <sphere radius="0.005"/>
      </geometry>
      <material name="">
        <color rgba="0.10 0.10 0.10 1" />
      </material>
    </visual>
-->
    <visual>
      <origin rpy="3.14159265359 1.1780972445 0" xyz="0 0 0"/>
      <geometry>
        <mesh filename="package://jaco_description/meshes/jaco2/8_finger_index.STL"/>
      </geometry>
      <material name="">
        <color rgba="0.50 0.50 0.50 1"/>
      </material>
    </visual>
    <collision>
      <origin rpy="3.14159265359 1.1780972445 0" xyz="0 0 0"/>
      <geometry>
        <mesh filename="package://jaco_description/meshes/jaco2/8_finger_index.STL"/>
      </geometry>
    </collision>
  </link>
  <joint name="jaco_finger_joint_0" type="revolute">
    <!--- remark 2014: damping greater than 0.1 (0.2) lead to model break downs when testing it bit by bit -->
    <!--- remark jan 2016: damping and friction higher than 0.005 required very high forces in order for the fingers
              to move at all, and then they mooved only slowly. -->
    <!--dynamics damping="0.1" friction="1.0"/-->
    <dynamics damping="0.005" friction="0.005"/>
    <origin rpy="0 -0.34 -0.191986" xyz="-0.0276  0.0204 0.11"/>
    <parent link="jaco_fingers_base_link"/>
    <child link="jaco_8_finger_index"/>
    <axis xyz="0 1 0"/>
    <limit effort="1.5" lower="-0.0045" upper="1.05" velocity="0.2"/>
  </joint>
  <!-- ...........................        -->
  <link name="jaco_9_finger_index_tip">
    <inertial>
      <origin rpy="0 0 0" xyz="-0.01340812509202 -4.52693266978291E-07 0.0118561361126153"/>
      <mass value="0.0122"/>
      <inertia ixx="2.6850059266e-06" ixy="0" ixz="0" iyy="2.6850059266e-06" iyz="0" izz="8.784e-07"/>
    </inertial>
    <!--     <visual>
      <origin xyz="0 0 0" rpy="0 0 0" />
      <geometry>
        <sphere radius="0.005"/>
      </geometry>
      <material name="">
        <color rgba="0.10 0.10 0.10 1" />
      </material>
    </visual>
-->
    <visual>
      <origin rpy="0 1.57079632679 3.14159265359" xyz="0 0 0"/>
      <geometry>
        <mesh filename="package://jaco_description/meshes/jaco2/9_finger_index_tip.STL" scale="1 1 1"/>
      </geometry>
      <material name="">
        <color rgba="0.5 0.5 0.5 1"/>
      </material>
    </visual>
    <collision>
      <origin rpy="0 1.57079632679 3.14159265359" xyz="0 0 0"/>
      <geometry>
        <mesh filename="package://jaco_description/meshes/jaco2/9_finger_index_tip.STL" scale="1 1 1"/>
      </geometry>
    </collision>
  </link>
  <joint name="jaco_finger_joint_1" type="fixed">
    <!--- remark 2014: damping greater than 0.1 (0.2) lead to model break downs when testing it bit by bit -->
    <!--- remark jan 2016: damping and friction higher than 0.005 required very high forces in order for the fingers
              to move at all, and then they mooved only slowly. -->
    <!--dynamics damping="0.1" friction="1.0"/-->
    <dynamics damping="0.005" friction="0.005"/>
    <origin rpy="0 0 0" xyz="0 0 0.0441"/>
    <parent link="jaco_8_finger_index"/>
    <child link="jaco_9_finger_index_tip"/>
  </joint>
  <!-- ...........................        -->
  <link name="jaco_7_finger_mount_thumb">
    <inertial>
      <origin rpy="0 0 0" xyz="-2.65251193937339E-07 0.00706398229186052 -0.00176078674955921"/>
      <mass value="0.006465"/>
      <inertia ixx="7.8441686232e-07" ixy="0" ixz="0" iyy="7.8441686232e-07" iyz="0" izz="1.04733e-06"/>
    </inertial>
    <visual>
      <origin rpy="1.57079632679 0 1.57079632679" xyz="0 0 0"/>
      <geometry>
        <mesh filename="package://jaco_description/meshes/jaco2/7_finger_mount_thumb.STL"/>
      </geometry>
      <material name="">
        <color rgba="0.50 0.50 0.50 1"/>
      </material>
    </visual>
    <collision>
      <origin rpy="1.57079632679 0 1.57079632679" xyz="0 0 0"/>
      <geometry>
        <mesh filename="package://jaco_description/meshes/jaco2/7_finger_mount_thumb.STL"/>
      </geometry>
    </collision>
  </link>
  <joint name="jaco_finger_mount_thumb_fixed" type="fixed">
    <!--- remark 2014: damping greater than 0.1 (0.2) lead to model break downs when testing it bit by bit -->
    <!--- remark jan 2016: damping and friction higher than 0.005 required very high forces in order for the fingers
              to move at all, and then they mooved only slowly. -->
    <!--dynamics damping="0.1" friction="1.0"/-->
    <dynamics damping="0.005" friction="0.005"/>
    <origin rpy="0 -0.2658 2.91470065359" xyz=" 0.037  0.001  0.095"/>
    <parent link="jaco_fingers_base_link"/>
    <child link="jaco_7_finger_mount_thumb"/>
  </joint>
  <!-- ...........................        -->
  <link name="jaco_8_finger_thumb">
    <inertial>
      <origin rpy="0 0 0" xyz="-0.0181403317517619 -3.13818432741766E-07 0.00272473343106584"/>
      <mass value="0.0184"/>
      <inertia ixx="6.3583245666e-06" ixy="0" ixz="0" iyy="6.3583245666e-06" iyz="0" izz="1.6767e-06"/>
    </inertial>
    <!--     <visual>
      <origin xyz="0 0 0" rpy="0 0 0" />
      <geometry>
        <sphere radius="0.005"/>
      </geometry>
      <material name="">
        <color rgba="0.10 0.10 0.10 1" />
      </material>
    </visual>
-->
    <visual>
      <origin rpy="3.14159265359 1.1780972445 0" xyz="0 0 0"/>
      <geometry>
        <mesh filename="package://jaco_description/meshes/jaco2/8_finger_thumb.STL"/>
      </geometry>
      <material name="">
        <color rgba="0.5 0.5 0.5 1"/>
      </material>
    </visual>
    <collision>
      <origin rpy="3.14159265359 1.1780972445 0" xyz="0 0 0"/>
      <geometry>
        <mesh filename="package://jaco_description/meshes/jaco2/8_finger_thumb.STL"/>
      </geometry>
    </collision>
  </link>
  <joint name="jaco_finger_joint_2" type="revolute">
    <!--- remark 2014: damping greater than 0.1 (0.2) lead to model break downs when testing it bit by bit -->
    <!--- remark jan 2016: damping and friction higher than 0.005 required very high forces in order for the fingers
              to move at all, and then they mooved only slowly. -->
    <!--dynamics damping="0.1" friction="1.0"/-->
    <dynamics damping="0.005" friction="0.005"/>
    <origin rpy="0 -0.37 2.91470065359" xyz=" 0.0319  0.003  0.11"/>
    <parent link="jaco_fingers_base_link"/>
    <child link="jaco_8_finger_thumb"/>
    <axis xyz="0 1 0"/>
    <limit effort="1.5" lower="-0.0045" upper="1.05" velocity="0.2"/>
  </joint>
  <!-- ...........................        -->
  <link name="jaco_9_finger_thumb_tip">
    <inertial>
      <origin rpy="0 0 0" xyz="-0.0134080639046228 -4.56622786070351E-07 0.0118561154422042"/>
      <mass value="0.0122"/>
      <inertia ixx="2.6850059266e-06" ixy="0" ixz="0" iyy="2.6850059266e-06" iyz="0" izz="8.784e-07"/>
    </inertial>
    <visual>
      <origin rpy="0 1.57079632679 3.14159265359" xyz="0 0 0"/>
      <geometry>
        <mesh filename="package://jaco_description/meshes/jaco2/9_finger_thumb_tip.STL" scale="1 1 1"/>
      </geometry>
      <material name="">
        <color rgba="0.5 0.5 0.5 1"/>
      </material>
    </visual>
    <collision>
      <origin rpy="0 1.57079632679 3.14159265359" xyz="0 0 0"/>
      <geometry>
        <mesh filename="package://jaco_description/meshes/jaco2/9_finger_thumb_tip.STL" scale="1 1 1"/>
      </geometry>
    </collision>
  </link>
  <joint name="jaco_finger_joint_3" type="fixed">
    <!--- remark 2014: damping greater than 0.1 (0.2) lead to model break downs when testing it bit by bit -->
    <!--- remark jan 2016: damping and friction higher than 0.005 required very high forces in order for the fingers
              to move at all, and then they mooved only slowly. -->
    <!--dynamics damping="0.1" friction="1.0"/-->
    <dynamics damping="0.005" friction="0.005"/>
    <origin rpy="0 0 0" xyz="0 0 0.0441"/>
    <parent link="jaco_8_finger_thumb"/>
    <child link="jaco_9_finger_thumb_tip"/>
  </joint>
  <!-- ...........................        -->
  <link name="jaco_7_finger_mount_pinkie">
    <inertial>
      <origin rpy="0 0 0" xyz="0 0.00706399455294665 -0.00176077690193762"/>
      <mass value="0.00646"/>
      <inertia ixx="7.8381019808e-07" ixy="0" ixz="0" iyy="7.8381019808e-07" iyz="0" izz="1.04652e-06"/>
    </inertial>
    <visual>
      <origin rpy="1.57079632679 0 1.57079632679" xyz="0 0 0"/>
      <geometry>
        <mesh filename="package://jaco_description/meshes/jaco2/7_finger_mount_pinkie.STL"/>
      </geometry>
      <material name="">
        <color rgba="0.5 0.5 0.5 1"/>
      </material>
    </visual>
    <collision>
      <origin rpy="1.57079632679 0 1.57079632679" xyz="0 0 0"/>
      <geometry>
        <mesh filename="package://jaco_description/meshes/jaco2/7_finger_mount_pinkie.STL"/>
      </geometry>
    </collision>
  </link>
  <joint name="jaco_finger_mount_pinkie_fixed" type="fixed">
    <!--- remark 2014: damping greater than 0.1 (0.2) lead to model break downs when testing it bit by bit -->
    <!--- remark jan 2016: damping and friction higher than 0.005 required very high forces in order for the fingers
              to move at all, and then they mooved only slowly. -->
    <!--dynamics damping="0.1" friction="1.0"/-->
    <dynamics damping="0.005" friction="0.005"/>
    <origin rpy="0 -0.2293 0.191986" xyz="-0.034 -0.022 0.095"/>
    <parent link="jaco_fingers_base_link"/>
    <child link="jaco_7_finger_mount_pinkie"/>
  </joint>
  <!-- ...........................        -->
  <link name="jaco_8_finger_pinkie">
    <inertial>
      <origin rpy="0 0 0" xyz="-0.0181404164708055 -2.87009015777565E-07 0.00272467774606585"/>
      <mass value="0.01845"/>
      <inertia ixx="6.37560262249e-06" ixy="0" ixz="0" iyy="6.37560262249e-06" iyz="0" izz="1.68125625e-06"/>
    </inertial>
    <!--     <visual>
      <origin xyz="0 0 0" rpy="0 0 0" />
      <geometry>
        <sphere radius="0.005"/>
      </geometry>
      <material name="">
        <color rgba="0.10 0.10 0.10 1" />
      </material>
    </visual>
-->
    <visual>
      <origin rpy="3.14159265359 1.1780972445 0" xyz="0 0 0"/>
      <geometry>
        <mesh filename="package://jaco_description/meshes/jaco2/8_finger_pinkie.STL"/>
      </geometry>
      <material name="">
        <color rgba="0.5 0.5 0.5 1"/>
      </material>
    </visual>
    <collision>
      <origin rpy="3.14159265359 1.1780972445 0" xyz="0 0 0"/>
      <geometry>
        <mesh filename="package://jaco_description/meshes/jaco2/8_finger_pinkie.STL"/>
      </geometry>
    </collision>
  </link>
  <joint name="jaco_finger_joint_4" type="revolute">
    <!--- remark 2014: damping greater than 0.1 (0.2) lead to model break downs when testing it bit by bit -->
    <!--- remark jan 2016: damping and friction higher than 0.005 required very high forces in order for the fingers
              to move at all, and then they mooved only slowly. -->
    <!--dynamics damping="0.1" friction="1.0"/-->
    <dynamics damping="0.005" friction="0.005"/>
    <origin rpy="0 -0.34 0.191986" xyz="-0.0276 -0.0204 0.11"/>
    <parent link="jaco_fingers_base_link"/>
    <child link="jaco_8_finger_pinkie"/>
    <axis xyz="0 1 0"/>
    <limit effort="1.5" lower="-0.0045" upper="1.05" velocity="0.2"/>
  </joint>
  <!-- ...........................        -->
  <link name="jaco_9_finger_pinkie_tip">
    <inertial>
      <origin rpy="0 0 0" xyz="-0.0134 0 0.01185"/>
      <mass value="0.0122"/>
      <inertia ixx="2.6850059266e-06" ixy="0" ixz="0" iyy="2.6850059266e-06" iyz="0" izz="8.784e-07"/>
    </inertial>
    <visual>
      <origin rpy="0 1.57079632679 3.14159265359" xyz="0 0 0"/>
      <geometry>
        <mesh filename="package://jaco_description/meshes/jaco2/9_finger_pinkie_tip.STL" scale="1 1 1"/>
      </geometry>
      <material name="">
        <color rgba="0.5 0.5 0.5 1"/>
      </material>
    </visual>
    <collision>
      <origin rpy="0 1.57079632679 3.14159265359" xyz="0 0 0"/>
      <geometry>
        <mesh filename="package://jaco_description/meshes/jaco2/9_finger_pinkie_tip.STL" scale="1 1 1"/>
      </geometry>
    </collision>
  </link>
  <joint name="jaco_finger_joint_5" type="fixed">
    <!--- remark 2014: damping greater than 0.1 (0.2) lead to model break downs when testing it bit by bit -->
    <!--- remark jan 2016: damping and friction higher than 0.005 required very high forces in order for the fingers
              to move at all, and then they mooved only slowly. -->
    <!--dynamics damping="0.1" friction="1.0"/-->
    <dynamics damping="0.005" friction="0.005"/>
    <origin rpy="0 0 0" xyz="0 0 0.0441"/>
    <parent link="jaco_8_finger_pinkie"/>
    <child link="jaco_9_finger_pinkie_tip"/>
  </joint>
  <!-- Optional: Add the Xtion to the table to observe the real arm -->
</robot>

